<?xml version="1.0"?>
<robot name="lifttruck" xmlns:xacro="http://ros.org/wiki/xacro">

  <xacro:property name="width" value="0.02" />
  <xacro:property name="leglen" value="0.06" />
  <xacro:property name="polelen" value="0.02" />
  <xacro:property name="bodylen" value="0.06" />
  <xacro:property name="baselen" value="0.04" />
  <xacro:property name="wheeldiam" value="0.007" />

  <material name="blue">
    <color rgba="0 0 0.8 1"/>
  </material>

  <material name="black">
    <color rgba="0 0 0 1"/>
  </material>

  <material name="white">
    <color rgba="1 1 1 1"/>
  </material>

  <xacro:macro name="default_inertial" params="mass">
    <inertial>
      <mass value="${mass}" />
      <inertia ixx="1.0" ixy="0.0" ixz="0.0" iyy="1.0" iyz="0.0" izz="1.0" />
    </inertial>
  </xacro:macro>

  <link name="base_link">
    <visual>
      <geometry>
        <cylinder radius="${width}" length="${bodylen}"/>
      </geometry>
      <material name="blue"/>
    </visual>
    <collision>
      <geometry>
        <cylinder radius="${width}" length="${bodylen}"/>
      </geometry>
    </collision>
    <xacro:default_inertial mass="10"/>
  </link>

  <xacro:macro name="wheel" params="prefix suffix reflect">

    <link name="${prefix}_${suffix}_wheel">
      <visual>
        <origin xyz="0 0 0" rpy="${pi/2} 0 0" />
        <geometry>
          <cylinder radius="${wheeldiam/2}" length="0.1"/>
        </geometry>
        <material name="black"/>
      </visual>
      <collision>
        <origin xyz="0 0 0" rpy="${pi/2} 0 0" />
        <geometry>
          <cylinder radius="${wheeldiam/2}" length="0.1"/>
        </geometry>
      </collision>
      <xacro:default_inertial mass="1"/>
    </link>
    <joint name="${prefix}_${suffix}_wheel_joint" type="continuous">
      <axis xyz="0 1 0" rpy="0 0 0" />
      <parent link="${prefix}_base"/>
      <child link="${prefix}_${suffix}_wheel"/>
      <origin xyz="${baselen*reflect/3} 0 -${wheeldiam/2+.05}" rpy="0 0 0"/>
    </joint>


</robot>
