<?xml version="1.0"?>

<robot name="robot_base">
  <link name="base_link" />
    <joint name="base_fixed_joint" type="fixed">
        <parent link="base_link" />
        <child link="blok" />
    </joint>
  <link name="blok">
    <inertial>
      <origin
        xyz="0.0030946 4.78250032638821E-11 0.053305"
        rpy="0 0 0" />
      <mass
        value="47.873" />
      <inertia
        ixx="0.774276574699151"
        ixy="-1.03781944357671E-10"
        ixz="0.00763014265820928"
        iyy="1.64933255189991"
        iyz="1.09578155845563E-12"
        izz="2.1239326987473" />
    </inertial>
    <visual>
      <origin
        xyz="0.216 0.1 0"
        rpy="0 0 3.14" />
      <geometry>
        <mesh filename="package://mobile_manipulator_body/meshes/blok.dae" />
      </geometry>
      <material
        name="">
        <color
          rgba="0.79216 0.81961 0.93333 1" />
      </material>
    </visual>
    <collision>
      <origin
        xyz="0 0 0"
        rpy="0 0 3.14" />
      <geometry>
        <mesh filename="package://mobile_manipulator_body/meshes/blok.dae" />
      </geometry>
    </collision>
  </link>
  
    <link name="widly">
    <inertial>
      <origin
        xyz="0.030946 4.78250032638821E-11 0.053305"
        rpy="0 0 0" />
      <mass
        value="47.873" />
      <inertia
        ixx="0.774276574699151"
        ixy="-1.03781944357671E-10"
        ixz="0.00763014265820928"
        iyy="1.64933255189991"
        iyz="1.09578155845563E-12"
        izz="2.1239326987473" />
    </inertial>
    <visual>
      <origin
        xyz="0 -0.5 0"
        rpy="0 0 0" />
      <geometry>
        <mesh filename="package://mobile_manipulator_body/meshes/widly.dae" />
      </geometry>
      <material
        name="">
        <color
          rgba="0.79216 0.81961 0.93333 1" />
      </material>
    </visual>
    <collision>
      <origin
        xyz="0 -0.5 0"
        rpy="0 0 0" />
      <geometry>
        <mesh filename="package://mobile_manipulator_body/meshes/widly.dae" />
      </geometry>
    </collision>
  </link>
  
  <link name="kolo_napedowe">
    <inertial>
      <origin
        xyz="0.030946 4.78250032638821E-11 0.053305"
        rpy="0 0 0" />
      <mass
        value="47.873" />
      <inertia
        ixx="0.774276574699151"
        ixy="-1.03781944357671E-10"
        ixz="0.00763014265820928"
        iyy="1.64933255189991"
        iyz="1.09578155845563E-12"
        izz="2.1239326987473" />
    </inertial>
    <visual>
      <origin
        xyz="0 -0.15 0"
        rpy="0 0 0" />
      <geometry>
        <mesh filename="package://mobile_manipulator_body/meshes/kolonapedowe.dae" />
      </geometry>
      <material
        name="">
        <color
          rgba="0.79216 0.81961 0.93333 1" />
      </material>
    </visual>
    <collision>
      <origin
        xyz="0 0 0.5"
        rpy="0 0 0" />
      <geometry>
        <mesh filename="package://mobile_manipulator_body/meshes/kolonapedowe.dae" />
      </geometry>
    </collision>
  </link>

  <joint name="blok_widly" type="continuous">
    <axis xyz="0 1 0"/>
    <parent link ="blok"/>
    <child link ="widly"/>
    <origin rpy ="0 0 0" xyz= "0.220 0.250 0"/>
  </joint>

  <joint name="blok_kolo_napedowe" type="continuous">
    <axis xyz="0 1 0"/>
    <parent link ="blok"/>
    <child link ="kolo_napedowe"/>
    <origin rpy ="0 0 0" xyz= "0.220 0.250 0"/>
  </joint>

<!--######################################################################-->


<!--######################################################################-->
</robot>

